Workbook
Name __xx3: __xx3
Name _1q2_: _1q2_
Name _q2: _q2
Name _Toc431893357: 'Sch1. (B)'!#REF!
Name _Toc431893357: 'Sch1. (A)'!#REF!
Name _xx3: _xx3
Name aa: #N/A
Name afyg: #REF!
Name AJ: [5]材料!$D$8
Name AL: [5]材料!$D$7
Name as: as
Name b: b
Name B1T: '[6]Bill 1'!$F$833
Name B3T: '[6]Bill 3'!$F$683
Name B4T: '[6]Bill 4'!$F$568
Name B5T: '[6]Bill 5'!$F$247
Name B6T: '[6]Bill 6'!$F$377
Name B7T: '[6]Bill 7'!$F$437
Name BBOQ: [7]BOQ!$1:$1048576
Name Beginning_Balance: -FV(Interest_Rate/12,Payment_Number-1,-Monthly_Payment,Loan_Amount)
Name bxq: [7]汇率!$C$25
Name ccc: ccc
Name cccc: cccc
Name ccccc: ccccc
Name ccccccc: ccccccc
Name cltz: #REF!
Name ddd: ddd
Name dgfdgdgfd: #REF!
Name dgfdgffhh: #REF!
Name dglf: [7]汇率!$C$27
Name DJFX: [9]DJFX!$A:$L
Name dkdxs: [7]汇率!$C$29
Name E: #REF!
Name EE: #REF!
Name Ending_Balance: -FV(Interest_Rate/12,Payment_Number,-Monthly_Payment,Loan_Amount)
Name EQ: [7]EQ!$1:$1048576
Name excb: 1
Name excf: 1
Name excl: 72.452
Name Full_Print: #REF!
Name gcjg: #REF!
Name gh: gh
Name ghh: ghh
Name gjxs: #REF!
Name gq: #REF!
Name H: #REF!
Name hbgfh: #REF!
Name Header_Row: ROW(#REF!)
Name Header_Row_Back: ROW(#REF!)
Name hfh: #REF!
Name HH: #REF!
Name hhgh: #REF!
Name hj: hj
Name hl: [9]基础数据表!$C$7
Name htzj: [7]汇率!$C$32
Name Interest: -IPMT(Interest_Rate/12,Payment_Number,Number_of_Payments,Loan_Amount)
Name Interest_Rate: #REF!
Name io: io
Name J: #REF!
Name JD: #REF!

Sheet Cover of IPC 
A1: Note: This IPC template does not contain any project-specific numbers, commercial values, or confidential pricing data. The percentages, formulas, and blank fields are included solely to demonstrate and automate the payment-certificate process. The breakdown of contract work completion into percentages reflects a standard method for tracking completed works and is not unique to any specific project. I have permission from my former employer to preserve and share the layout of the IPC template for portfolio and resume purposes.
A2: Project Name | C2: Назване Контракта
A3: Contract No: Name of Contract: Contractor: | C3: Контракт: Название контракта: Подрядчик:
A4: Interim Payment Certificate No Сертификат промежуточного платежа № | C4: Date of Approval: Дата утверждения:
A5: Contractor's Payment Application Reference / Исх. №. Заявки Подрядчика на оплату:
A6: Date Submitted / Дата представления: | C6: DD.MM.YYYY
A7: Period Covered by Contractor's Statement/ Охваченный период: | C7: Period Covered/Охваченный период | D7: DD.MM.YYYY - DD.MM.YYYY
A8: Description | B8: Описание | D8: Total Amount (USD) / Общая сумма (доллар США)
A9: A. Value of Executed Works to Date | B9: A. Оценённая стоимость выполненных работ | D9: ='Bill Summary'!M22 -> 0
A10: Sub-Total (A) | B10: Итого (A) | D10: =SUM(D9) -> 0
A11: B. Additions | B11: Дополнения
A12: Advance Payment | B12: Авансовый платеж | D12: ='Bill Summary'!G27 -> 0
A13: Price Adjustment | B13: Корректировка цен | D13: ='Bill Summary'!G21 -> 0
A14: Sub-Total (B) | B14: Итого (B) | D14: =D12+D13 -> 0
A15: Retention = % as per "reference to a contract" | B15: удержание в % по "ссылка" пункту контракта | D15: ='Bill Summary'!M40 -> 0
A16: Repayment of Advance % as per "reference to a contract" | B16: Погашение авансового платежа % согласно "ссылка к контрактуЭ | D16: ='Bill Summary'!M41 -> 0
A17: Sub-Total (C) | B17: Итого (C) | D17: =D15+D16 -> 0
A18: Sub-Total Amount Certified (A+B-С) | B18: Общая заверенная сумма (A+B-С) | D18: =D10+D14-D17 -> 0
A19: Deduct Total Amount Certified on Previous IPC | B19: Вычет суммы, утверждённый для предыдущего сертификата промежуточной оплаты | D19: =C53 -> 0
A20: TOTAL DUE ON THIS CERTIFICATE | B20: ИТОГО к оплате по данному Сертификату | D20: =D18-D19 -> 0
A21: Signed/ Подпись: | B21: Signed/ Подпись: | D21: Signed/ Подпись:
A22: On behalf of the Contractor/ От имени подрядчика | B22: On behalf of the Engineer/ От имени инженера | D22: On behalf of the Employer/ отимениработодатель

Sheet Bill Summary
B1: Name of a project / Название котракту
B2: Contract identifier / Идентификатор контракта
B3: IPC # / СПП № #
B4: Start of Works/ Начало работ : DD.MM.YYYY | J4: Period Covered/Охваченный период | N4: ='Cover of IPC '!D7 -> DD.MM.YYYY - DD.MM.YYYY
E5: Amount of works for payment according to contract | K5: Real cost of executed works
A6: Bill Nr | D6: Contract Amount | E6: Bill Summary | I6: Remaining Works | K6: Bill Summary | O6: Remaining Works
E7: Total Amount Previous Certificate | F7: Amount This Certificate | G7: Total Amount To Date | H7: Progress Till date | I7: Amount / | J7: % | K7: Total Amount Previous Certificate | L7: Amount This Certificate | M7: Total Amount To Date | N7: Progress Till date | O7: Amount / | P7: %
D8: USD | E8: USD | F8: USD | G8: USD | H8: % | I8: USD | J8: % | K8: USD | L8: USD | M8: USD | N8: % | O8: USD | P8: %
E9: Объем работ к оплате согласно контракту | K9: Реальная стоимость выполненных работ
A10: Счет № | D10: Стоимость контракта | E10: Сводная | I10: Остальные работы | K10: Сводная | O10: Остальные работы
E11: Общая Сумма Предыдущего Сертификата | F11: Сумма Данного Сертификата | G11: Общая сумма на текущее число | H11: Прогресс на данное число | I11: Сумма | J11: % | K11: Общая Сумма Предыдущего Сертификата | L11: Сумма Данного Сертификата | M11: Общая сумма на текущее число | N11: Прогресс на данное число | O11: Сумма | P11: %
D12: USD | E12: USD | F12: USD | G12: USD | H12: % | I12: USD | J12: USD | K12: USD | L12: USD | M12: USD | N12: % | O12: USD | P12: USD
B13: Payments | C13: Начисление
B14: Part A - Measured Work | C14: Часть А. - Измеренные работы | E14: A section / А секция | K14: B section / B секция
A15: 1 | B15: SCHEDULE 1 | C15: ТАБЛИЦА 1 | D15: ='Sch1. (A)'!F19 -> 0 | E15: ='Sch1. (A)'!K19 -> 0 | F15: =G15-E15 -> 0 | G15: ='Sch1. (A)'!U19 -> 0 | H15: =(G15)/(D15*0.7) -> #DIV/0! | I15: =+D15*0.7-(G15) -> 0 | J15: =+I15/(D15*0.7) -> #DIV/0! | K15: ='Sch1. (B)'!K19 -> 0 | L15: =M15-K15 -> 0 | M15: ='Sch1. (B)'!U19 -> 0 | N15: =M15/D15 -> #DIV/0! | O15: =D15-M15 -> 0 | P15: =O15/D15 -> #DIV/0!
A16: 2 | B16: SCHEDULE 2 | C16: ТАБЛИЦА 2 | E16: ='[18]Schedule 2. Supply of Plant EXW'!H689 -> 0 | F16: =G16-E16 -> 0 | G16: ='[18]Schedule 2. Supply of Plant EXW'!L689 -> 0 | P16: =O16/D16 -> #DIV/0!
A17: 3 | B17: SCHEDULE 3 | C17: ТАБЛИЦА 3. | D17: ='Sch3. (A)'!F20 -> 0 | E17: ='Sch3. (A)'!H20 -> 0 | F17: =G17-E17 -> 0 | G17: ='Sch3. (A)'!L20 -> 0 | H17: =G17/(D17*0.8) -> #DIV/0! | I17: =+D17*0.8-G17 -> 0 | J17: =+I17/(D17*0.8) -> #DIV/0! | K17: ='Sch3. (B)'!H20 -> 0 | L17: =M17-K17 -> 0 | M17: ='Sch3. (B)'!L20 -> 0 | N17: =M17/D17 -> #DIV/0! | O17: =D17-M17 -> 0 | P17: =O17/D17 -> #DIV/0!
A18: 4 | B18: SCHEDULE 4. | C18: ТАБЛИЦА 4. | D18: ='Sch4. (B)'!F33 -> 0 | E18: ='Sch4. (A)'!H33 -> 0 | F18: =G18-E18 -> 0 | G18: ='Sch4. (A)'!L33 -> 0 | H18: =G18/(D18*0.7) -> #DIV/0! | I18: =+D18*0.7-G18 -> 0 | J18: =+I18/(D18*0.7) -> #DIV/0! | K18: ='Sch4. (B)'!H33 -> 0 | L18: =M18-K18 -> 0 | M18: ='Sch4. (B)'!L33 -> 0 | N18: =M18/D18 -> #DIV/0! | O18: =D18-M18 -> 0 | P18: =O18/D18 -> #DIV/0!
A19: 5 | B19: DAYWORKS | C19: ПОДЕННАЯ РАБОТА | D19: =Dayworks!F19 -> 0 | E19: =Dayworks!H19 -> 0 | F19: =G19-E19 -> 0 | G19: 0 | H19: =+G19/D19 -> #DIV/0! | I19: =+D19-G19 -> 0 | J19: =+I19/D19 -> #DIV/0! | K19: =Dayworks!H19 -> 0 | L19: =M19-K19 -> 0 | M19: =Dayworks!L19 -> 0 | N19: =M19/D19 -> #DIV/0! | O19: =D19-M19 -> 0 | P19: =O19/D19 -> #DIV/0!
B20: Total Measured Work (А) | C20: Всего измеренные работы (А) | D20: =SUM(D15:D19) -> 0 | E20: =SUM(E15:E19) -> 0 | F20: =SUM(F15:F19) -> 0 | G20: =SUM(G15:G19) -> 0 | H20: =+G20/(D20*Q20) -> #DIV/0! | I20: =SUM(I15:I19) -> 0 | J20: =+I20/(D20*Q20) -> #DIV/0! | K20: =SUM(K15:K19) -> 0 | L20: =SUM(L15:L19) -> 0 | M20: =SUM(M15:M19) -> 0 | N20: =M20/D20 -> #DIV/0! | O20: =D20-M20 -> 0 | P20: =O20/D20 -> #DIV/0! | Q20: 0.7029179
B21: Part B -CONTINGENCY FOR VARIED WORKS AND PRICE ADJUSTMENT (#% OF SUBTOTAL) | C21: Часть Б- НЕПРЕДВИДЕННЫЕ РАСХОДЫ ПО ИЗМЕНЕННЫМ РАБОТАМ И КОРРЕКТИРОВКЕ ЦЕН (#% ОТ ИТОГОВОЙ СУММЫ) | E21: 0 | F21: =G21-E21 -> 0 | G21: 0 | H21: =G21/D21 -> #DIV/0! | I21: =D21-G21 -> 0 | J21: =I21/D21 -> #DIV/0! | K21: =E21 -> 0 | L21: =M21-K21 -> 0 | M21: =G21 -> 0 | N21: =M21/D21 -> #DIV/0! | O21: =D21-M21 -> 0 | P21: =O21/D21 -> #DIV/0!
B22: Total Measured Work (А+B) | C22: Всего измеренные работы (А+Б) | D22: =D20+D21 -> 0 | E22: =E20+E21 -> 0 | F22: =F20+F21 -> 0 | G22: =G20+G21 -> 0 | H22: =G22/(D22*Q22) -> #DIV/0! | I22: =I21+I20 -> 0 | J22: =I22/(D22*Q22) -> #DIV/0! | K22: =K20+K21 -> 0 | L22: =L20+L21 -> 0 | M22: =M20+M21 -> 0 | N22: =M22/D22 -> #DIV/0! | O22: =D22-M22 -> 0 | P22: =O22/D22 -> #DIV/0! | Q22: 0.7313935
B23: Part C - Advance Payment | C23: Часть В- Выплата аванса
A24: 1 | B24: SCHEDULE 1 | C24: ТАБЛИЦА 1 | E24: =D15*0.2 -> 0 | F24: =G24-E24 -> 0 | G24: =D15*0.2 -> 0 | K24: =E24 -> 0 | L24: =F24 -> 0 | M24: =G24 -> 0
A25: 2 | B25: SCHEDULE 3 | C25: ТАБЛИЦА 3. | E25: =D17*0.2 -> 0 | F25: =G25-E25 -> 0 | G25: =D17*0.2 -> 0 | K25: =E25 -> 0 | L25: =F25 -> 0 | M25: =G25 -> 0
A26: 3 | B26: SCHEDULE 4. | C26: ТАБЛИЦА 4. УСТАНОВКА И ДРУГИЕ УСЛУГИ | E26: =D18*0.2 -> 0 | F26: =G26-E26 -> 0 | G26: =D18*0.2 -> 0 | K26: =E26 -> 0 | L26: =F26 -> 0 | M26: =G26 -> 0
B27: Total Advance Payment (C) | C27: Всего выплата аванса (В) | E27: =SUM(E24:E26) -> 0 | F27: =SUM(F24:F26) -> 0 | G27: =SUM(G24:G26) -> 0 | K27: =SUM(K24:K26) -> 0 | L27: =SUM(L24:L26) -> 0 | M27: =SUM(M24:M26) -> 0
B28: Рart D - Repayment of retention | C28: Часть Г -Возврат удержания
B29: Repayment of retention for completion Sch 1 | C29: Возврат удержания на завершение Табл. 1 | E29: Manual entry | F29: =G29-E29 -> #VALUE! | G29: 0 | K29: Manual entry | L29: =M29-K29 -> #VALUE! | M29: =M36 -> 0
B30: Repayment of retention for completion Sch 4 | C30: Возврат удержания на завершение Табл. 4 | E30: Manual entry | F30: =G30-E30 -> #VALUE! | G30: 0 | K30: Manual entry | L30: =M30-K30 -> #VALUE! | M30: =M37 -> 0
B31: Repayment of retention for Operational Acceptance Sсh 1 | C31: Возврат удержания на прием в эксплуатацию Табл. 1 | E31: Manual entry | F31: =G31-E31 -> #VALUE! | G31: 0 | K31: Manual entry | L31: =M31-K31 -> #VALUE! | M31: =M38 -> 0
B32: Repayment of retention for Operational Acceptance Sсh 4 | C32: Возврат удержание на прием в эксплуатацию Табл. 4 | E32: Manual entry | F32: =G32-E32 -> #VALUE! | G32: 0 | K32: Manual entry | L32: =M32-K32 -> #VALUE! | M32: =M39 -> 0
B33: Total repayment of retention (E) | C33: Всего возврат удержания (Д) | E33: =SUM(E29:E32) -> 0 | F33: =SUM(F29:F32) -> #VALUE! | G33: =SUM(G29:G32) -> 0 | K33: =SUM(K29:K32) -> 0 | L33: =SUM(L29:L32) -> #VALUE! | M33: =SUM(M29:M32) -> 0
B34: Part F - Deductions | C34: Часть Е - Вычеты
B35: 1) Retention | C35: 1)Удержане
B36: Retention for completion Sch 1 (5%) | C36: Удержание на завершение Табл. 1 (5%) | K36: Manual entry | L36: =M36-K36 -> #VALUE! | M36: ='Sch1. (A)'!U20 -> 0
B37: Retention for completion Sch 4 (5%) | C37: Удержание на завершение Табл. 4 (5%) | K37: Manual entry | L37: =M37-K37 -> #VALUE! | M37: =ROUND(G18/70*5,2) -> 0
B38: Retention for Operational Acceptance Sh 1 (5%) | C38: Удержание на прием в эксплуатацию Табл. 1 (5%) | K38: Manual entry | L38: =M38-K38 -> #VALUE! | M38: ='Sch1. (A)'!U22 -> 0
B39: Retention for Operational Acceptance Sh 4 (5%) | C39: Удержание на прием в эксплуатацию Табл. 4 (5%) | K39: Manual entry | L39: =M39-K39 -> #VALUE! | M39: =ROUND(G18/70*5,2) -> 0
B40: Total retention | C40: Всего удержание | K40: Manual entry | L40: =SUM(L36:L39) -> #VALUE! | M40: =SUM(M36:M39) -> 0
...

Sheet Sch1. (A)
B1: ='Bill Summary'!B1:O1 -> Name of a project / Название котракту
B2: ='Bill Summary'!B2:O2 -> Contract identifier / Идентификатор контракта
B3: ='Bill Summary'!B3:J3 -> IPC # / СПП № #
B4: ='Bill Summary'!B4:C4 -> Start of Works/ Начало работ : DD.MM.YYYY | T4: Period Covered/Охваченный период | Y4: ='Cover of IPC '!D7 -> DD.MM.YYYY - DD.MM.YYYY
A5: SCHEDULE 1 / ТАБЛИЦА 1
A6: Item No/Статья № | B6: Description of Work | C6: Unit | D6: Quantity | E6: Unit Cost (USD) | F6: Total Cost (USD) | G6: Cumulative Previous/Совокупный Предыдущий | L6: Current / Текущее | Q6: Total / Итого | V6: Remaining / Оставшиеся | AA6: Remaining Percentage/ Оставшийся процент | AB6: Amount payable before leaving the factory (50%) Сумма, подлежащая оплате перед отъездом с завода | AD6: After delivery of equipment on site (20%) После доставки оборудования на объект
B7: Описание работ | C7: Единица | D7: Количество | E7: Цена за единицу(USD) | F7: Итого (USD) | G7: Amount payable before leaving the factory (50%) Сумма, подлежащая оплате перед отъездом с завода | I7: After delivery of equipment on site (20%) После доставки оборудования на объект | K7: Total payment/ Всего платеж | L7: Amount payable before leaving the factory (50%) Сумма, подлежащая оплате перед отъездом с завода | N7: After delivery of equipment on site (20%) После доставки оборудования на объект | P7: Total payment/ Всего платеж | Q7: Amount payable before leaving the factory (50%) Сумма, подлежащая оплате перед отъездом с завода | S7: After delivery of equipment on site (20%) После доставки оборудования на объект | U7: Total payment/ Всего платеж | V7: Amount payable before leaving the factory (50%) Сумма, подлежащая оплате перед отъездом с завода | X7: After delivery of equipment on site (20%) После доставки оборудования на объект | Z7: Total payment/ Всего платеж
G8: Quantity Кол-ство | H8: Amount USD | I8: Quantity Кол-ство | J8: Amount USD | K8: Amount USD | L8: Quantity Кол-ство | M8: Amount USD | N8: Quantity Кол-ство | O8: Amount USD | P8: Amount USD | Q8: Quantity Кол-ство | R8: Amount USD | S8: Quantity Кол-ство | T8: Amount USD | U8: Amount USD | V8: Quantity Кол-ство | W8: Amount USD | X8: Quantity Кол-ство | Y8: Amount USD | Z8: Amount USD | AA8: % | AB8: 0.5 | AD8: 0.2
D10: Manual Entry | E10: Manual Entry | F10: D*E | G10: Manual Entry | H10: G*$E*$AB$8 | I10: Manual Entry | J10: I*E*$AD$8 | K10: J+H | L10: Q-G | M10: L*$E*$AB$8 | N10: S-I | O10: N*$E*$AD$8 | P10: O+M | Q10: Manual Entry | R10: Q*$E*$AB$8 | S10: Manual Entry | T10: S*$E*$AD$8 | U10: T+R | V10: D-Q | W10: V*$E*$AB$8 | X10: D-S | Y10: X*$E*$AD$8 | Z10: Y+W | AA10: Z/F
G11: 0 | H11: =G11*$E11*$AB$8 -> 0 | I11: 0 | J11: =I11*E11*$AD$8 -> 0 | K11: =J11+H11 -> 0 | L11: =Q11-G11 -> 0 | M11: =L11*$E11*$AB$8 -> 0 | N11: =S11-I11 -> 0 | O11: =N11*$E11*$AD$8 -> 0 | P11: =O11+M11 -> 0 | R11: =Q11*$E11*$AB$8 -> 0 | T11: =S11*$E11*$AD$8 -> 0 | U11: =T11+R11 -> 0 | V11: =D11-$Q11 -> 0 | W11: =V11*$E11*$AB$8 -> 0 | X11: =D11-S11 -> 0 | Y11: =X11*$E11*$AD$8 -> 0 | Z11: =Y11+W11 -> 0 | AA11: =Z11/F11 -> #DIV/0!
F13: =D13*E13 -> 0 | H13: =G13*$E13*$AB$8 -> 0 | J13: =I13*E13*$AD$8 -> 0 | K13: =J13+H13 -> 0 | L13: =Q13-G13 -> 0 | M13: =L13*$E13*$AB$8 -> 0 | N13: =S13-I13 -> 0 | O13: =N13*$E13*$AD$8 -> 0 | P13: =O13+M13 -> 0 | R13: =Q13*$E13*$AB$8 -> 0 | T13: =S13*$E13*$AD$8 -> 0 | U13: =T13+R13 -> 0 | V13: =D13-$Q13 -> 0 | W13: =V13*$E13*$AB$8 -> 0 | X13: =D13-S13 -> 0 | Y13: =X13*$E13*$AD$8 -> 0 | Z13: =Y13+W13 -> 0 | AA13: =Z13/F13 -> #DIV/0!
F15: =D15*E15 -> 0 | H15: =G15*$E15*$AB$8 -> 0 | J15: =I15*E15*$AD$8 -> 0 | K15: =J15+H15 -> 0 | L15: =Q15-G15 -> 0 | M15: =L15*$E15*$AB$8 -> 0 | N15: =S15-I15 -> 0 | O15: =N15*$E15*$AD$8 -> 0 | P15: =O15+M15 -> 0 | R15: =Q15*$E15*$AB$8 -> 0 | T15: =S15*$E15*$AD$8 -> 0 | U15: =T15+R15 -> 0 | V15: =D15-$Q15 -> 0 | W15: =V15*$E15*$AB$8 -> 0 | X15: =D15-S15 -> 0 | Y15: =X15*$E15*$AD$8 -> 0 | Z15: =Y15+W15 -> 0 | AA15: =Z15/F15 -> #DIV/0!
F17: =D17*E17 -> 0 | H17: =G17*$E17*$AB$8 -> 0 | J17: =I17*E17*$AD$8 -> 0 | K17: =J17+H17 -> 0 | L17: =Q17-G17 -> 0 | M17: =L17*$E17*$AB$8 -> 0 | N17: =S17-I17 -> 0 | O17: =N17*$E17*$AD$8 -> 0 | P17: =O17+M17 -> 0 | R17: =Q17*$E17*$AB$8 -> 0 | T17: =S17*$E17*$AD$8 -> 0 | U17: =T17+R17 -> 0 | V17: =D17-$Q17 -> 0 | W17: =V17*$E17*$AB$8 -> 0 | X17: =D17-S17 -> 0 | Y17: =X17*$E17*$AD$8 -> 0 | Z17: =Y17+W17 -> 0 | AA17: =Z17/F17 -> #DIV/0!
A19: 1.S | B19: TOTAL / ВСЕГО | F19: =SUM(F11:F18) -> 0 | H19: =SUM(H11:H18) -> 0 | J19: =SUM(J11:J18) -> 0 | K19: =SUM(K11:K18) -> 0 | M19: =SUM(M11:M18) -> 0 | O19: =SUM(O11:O18) -> 0 | P19: =SUM(P11:P18) -> 0 | R19: =SUM(R11:R18) -> 0 | T19: =SUM(T11:T18) -> 0 | U19: =SUM(U11:U18) -> 0 | W19: =SUM(W11:W18) -> 0 | Y19: =SUM(Y11:Y18) -> 0 | Z19: =SUM(Z11:Z18) -> 0 | AA19: =Z19/F19 -> #DIV/0!
A20: Deductables Удержание | B20: Retention for completion Sch 1 (5%) | H20: =(H19/50)*5*(50/70) -> 0 | J20: =(J19/20)*5*(20/70) -> 0 | K20: =H20+J20 -> 0 | M20: =(M19/50)*5*(50/70) -> 0 | O20: =(O19/20)*5*(20/70) -> 0 | P20: =M20+O20 -> 0 | R20: =(R19/50)*5*(50/70) -> 0 | T20: =(T19/20)*5*(20/70) -> 0 | U20: =R20+T20 -> 0
B21: Удержание на завершение Табл. 1 (5%)
B22: Retention for Operational Acceptance Sh 1 (5%) | H22: =(H19/50)*5*(50/70) -> 0 | J22: =(J19/20)*5*(20/70) -> 0 | K22: =H22+J22 -> 0 | M22: =(M19/50)*5*(50/70) -> 0 | O22: =(O19/20)*5*(20/70) -> 0 | P22: =M22+O22 -> 0 | R22: =(R19/50)*5*(50/70) -> 0 | T22: =(T19/20)*5*(20/70) -> 0 | U22: =R22+T22 -> 0
B23: Удержание на прием в эксплуатацию Табл. 1 (5%)
B24: Repayment of Advance 20% of Sch 1 | H24: =(H19/50)*20*(50/70) -> 0 | J24: =(J19/20)*20*(20/70) -> 0 | K24: =H24+J24 -> 0 | M24: =(M19/50)*20*(50/70) -> 0 | O24: =(O19/20)*20*(20/70) -> 0 | P24: =M24+O24 -> 0 | R24: =(R19/50)*20*(50/70) -> 0 | T24: =(T19/20)*20*(20/70) -> 0 | U24: =R24+T24 -> 0
B25: Возврат Аванса 20% для Табл. 1

Sheet Sch3. (A)
B1: ='Bill Summary'!B1:O1 -> Name of a project / Название котракту
B2: ='Bill Summary'!B2:O2 -> Contract identifier / Идентификатор контракта
B3: ='Bill Summary'!B3:J3 -> IPC # / СПП № #
B4: ='Bill Summary'!B4:C4 -> Start of Works/ Начало работ : DD.MM.YYYY | I4: Period Covered/Охваченный период | M4: ='Cover of IPC '!D7 -> DD.MM.YYYY - DD.MM.YYYY
A5: SCHEDULE 3 / / ТАБЛИЦА 3
A6: Item No / Статья № | B6: Description of Work | C6: Unit | D6: Quantity | E6: Unit Cost (USD) | F6: Total Cost (USD) | G6: Cumulative Previous/Совокупный Предыдущий | I6: Current / Текущее | K6: Total / Итого | M6: Remaining / Оставшиеся | O6: Remaining Percentage/ Оставшийся процент | P6: Contractual Provision
B7: Описание работ | C7: Единица | D7: Количество | E7: Цена за единицу(USD) | F7: Итого (USD) | G7: Quantity Кол-ство | H7: Amount USD | I7: Quantity Кол-ство | J7: Amount USD | K7: Quantity Кол-ство | L7: Amount USD | M7: Quantity Кол-ство | N7: Amount USD | O7: % | P7: 0.8
D9: Manual entry | E9: Manual entry | F9: Manual entry | G9: Manual entry | H9: G*$E*$P$7 | I9: K-G | J9: I*$E*$P$7 | K9: Manual entry | L9: K*$E*$P$7 | M9: D-$K | N9: M*$E*$P$7 | O9: N/(F*$P$7)
H10: =G10*$E10*$P$7 -> 0 | I10: =K10-G10 -> 0 | J10: =I10*$E10*$P$7 -> 0 | L10: =K10*$E10*$P$7 -> 0 | M10: =D10-$K10 -> 0 | N10: =M10*$E10*$P$7 -> 0 | O10: =N10/(F10*$P$7) -> #DIV/0!
H12: =G12*$E12*$P$7 -> 0 | I12: =K12-G12 -> 0 | J12: =I12*$E12*$P$7 -> 0 | L12: =K12*$E12*$P$7 -> 0 | M12: =D12-$K12 -> 0 | N12: =M12*$E12*$P$7 -> 0 | O12: =N12/(F12*$P$7) -> #DIV/0!
H14: =G14*$E14*$P$7 -> 0 | I14: =K14-G14 -> 0 | J14: =I14*$E14*$P$7 -> 0 | L14: =K14*$E14*$P$7 -> 0 | M14: =D14-$K14 -> 0 | N14: =M14*$E14*$P$7 -> 0 | O14: =N14/(F14*$P$7) -> #DIV/0!
H16: =G16*$E16*$P$7 -> 0 | I16: =K16-G16 -> 0 | J16: =I16*$E16*$P$7 -> 0 | L16: =K16*$E16*$P$7 -> 0 | M16: =D16-$K16 -> 0 | N16: =M16*$E16*$P$7 -> 0 | O16: =N16/(F16*$P$7) -> #DIV/0!
H18: =G18*$E18*$P$7 -> 0 | I18: =K18-G18 -> 0 | J18: =I18*$E18*$P$7 -> 0 | L18: =K18*$E18*$P$7 -> 0 | M18: =D18-$K18 -> 0 | N18: =M18*$E18*$P$7 -> 0 | O18: =N18/(F18*$P$7) -> #DIV/0!
A20: 3.S | B20: TOTAL / ВСЕГО | F20: =SUM(F10:F19) -> 0 | H20: =SUM(H10:H19) -> 0 | J20: =SUM(J10:J19) -> 0 | L20: =SUM(L10:L19) -> 0 | N20: =SUM(N10:N19) -> 0 | O20: =N20/F20 -> #DIV/0!

Sheet Sch4. (A)
B1: ='Bill Summary'!B1:O1 -> Name of a project / Название котракту
B2: ='Bill Summary'!B2:O2 -> Contract identifier / Идентификатор контракта
B3: ='Bill Summary'!B3:J3 -> IPC # / СПП № #
B4: ='Bill Summary'!B4:C4 -> Start of Works/ Начало работ : DD.MM.YYYY | I4: Period Covered/Охваченный период | M4: ='Cover of IPC '!D7 -> DD.MM.YYYY - DD.MM.YYYY
A5: SCHEDULE 4 / / ТАБЛИЦА 14
A6: Item No / Статья № | B6: Description of Work | C6: Unit | D6: Quantity | E6: Unit Cost (USD) | F6: Total Cost (USD) | G6: Cumulative Previous / Совокупный Предыдущий | I6: Current / Текущее | K6: Total / Итого | M6: Remaining / Оставшиеся | O6: Remaining Percentage/ Оставшийся процент | P6: Contractual Provision
B7: Описание работ | C7: Единица | D7: Количество | E7: Цена за единицу(USD) | F7: Итого (USD) | G7: Quantity Кол-ство | H7: Amount USD | I7: Quantity Кол-ство | J7: Amount USD | K7: Quantity Кол-ство | L7: Amount USD | M7: Quantity Кол-ство | N7: Amount USD | O7: % | P7: 0.7
B9: Type of Entry | D9: Manual entry | E9: Manual entry | F9: Manual entry | G9: Manual entry | H9: G10*$E10*$P$7 | I9: K10-G10 | J9: I10*$E10*$P$7 | K9: Manual entry | L9: K10*$E10*$P$7 | M9: D10-$K10 | N9: M10*$E10*$P$7 | O9: N10/(F10*$P$7)
H10: =G10*$E10*$P$7 -> 0 | I10: =K10-G10 -> 0 | J10: =I10*$E10*$P$7 -> 0 | L10: =K10*$E10*$P$7 -> 0 | M10: =D10-$K10 -> 0 | N10: =M10*$E10*$P$7 -> 0 | O10: =N10/(F10*$P$7) -> #DIV/0!
H12: =G12*$E12*$P$7 -> 0 | I12: =K12-G12 -> 0 | J12: =I12*$E12*$P$7 -> 0 | L12: =K12*$E12*$P$7 -> 0 | M12: =D12-$K12 -> 0 | N12: =M12*$E12*$P$7 -> 0 | O12: =N12/(F12*$P$7) -> #DIV/0!
H15: =G15*$E15*$P$7 -> 0 | I15: =K15-G15 -> 0 | J15: =I15*$E15*$P$7 -> 0 | L15: =K15*$E15*$P$7 -> 0 | M15: =D15-$K15 -> 0 | N15: =M15*$E15*$P$7 -> 0 | O15: =N15/(F15*$P$7) -> #DIV/0!
H17: =G17*$E17*$P$7 -> 0 | I17: =K17-G17 -> 0 | J17: =I17*$E17*$P$7 -> 0 | L17: =K17*$E17*$P$7 -> 0 | M17: =D17-$K17 -> 0 | N17: =M17*$E17*$P$7 -> 0 | O17: =N17/(F17*$P$7) -> #DIV/0!
H19: =G19*$E19*$P$7 -> 0 | I19: =K19-G19 -> 0 | J19: =I19*$E19*$P$7 -> 0 | L19: =K19*$E19*$P$7 -> 0 | M19: =D19-$K19 -> 0 | N19: =M19*$E19*$P$7 -> 0 | O19: =N19/(F19*$P$7) -> #DIV/0!
H21: =G21*$E21*$P$7 -> 0 | I21: =K21-G21 -> 0 | J21: =I21*$E21*$P$7 -> 0 | L21: =K21*$E21*$P$7 -> 0 | M21: =D21-$K21 -> 0 | N21: =M21*$E21*$P$7 -> 0 | O21: =N21/(F21*$P$7) -> #DIV/0!
H23: =G23*$E23*$P$7 -> 0 | I23: =K23-G23 -> 0 | J23: =I23*$E23*$P$7 -> 0 | L23: =K23*$E23*$P$7 -> 0 | M23: =D23-$K23 -> 0 | N23: =M23*$E23*$P$7 -> 0 | O23: =N23/(F23*$P$7) -> #DIV/0!
H25: =G25*$E25*$P$7 -> 0 | I25: =K25-G25 -> 0 | J25: =I25*$E25*$P$7 -> 0 | L25: =K25*$E25*$P$7 -> 0 | M25: =D25-$K25 -> 0 | N25: =M25*$E25*$P$7 -> 0 | O25: =N25/(F25*$P$7) -> #DIV/0!
H27: =G27*$E27*$P$7 -> 0 | I27: =K27-G27 -> 0 | J27: =I27*$E27*$P$7 -> 0 | L27: =K27*$E27*$P$7 -> 0 | M27: =D27-$K27 -> 0 | N27: =M27*$E27*$P$7 -> 0 | O27: =N27/(F27*$P$7) -> #DIV/0!
H29: =G29*$E29*$P$7 -> 0 | I29: =K29-G29 -> 0 | J29: =I29*$E29*$P$7 -> 0 | L29: =K29*$E29*$P$7 -> 0 | M29: =D29-$K29 -> 0 | N29: =M29*$E29*$P$7 -> 0 | O29: =N29/(F29*$P$7) -> #DIV/0!
H31: =G31*$E31*$P$7 -> 0 | I31: =K31-G31 -> 0 | J31: =I31*$E31*$P$7 -> 0 | L31: =K31*$E31*$P$7 -> 0 | M31: =D31-$K31 -> 0 | N31: =M31*$E31*$P$7 -> 0 | O31: =N31/(F31*$P$7) -> #DIV/0!
A33: 4.S | B33: TOTAL / ВСЕГО | F33: =SUM(F10:F32) -> 0 | H33: =SUM(H10:H32) -> 0 | J33: =SUM(J10:J32) -> 0 | L33: =SUM(L10:L32) -> 0 | N33: =SUM(N10:N32) -> 0 | O33: =N33/F33 -> #DIV/0!

Sheet Dayworks
B1: ='Bill Summary'!B1:O1 -> Name of a project / Название котракту
B2: ='Bill Summary'!B2:O2 -> Contract identifier / Идентификатор контракта
B3: ='Bill Summary'!B3 -> IPC # / СПП № #
B4: ='Bill Summary'!B4:C4 -> Start of Works/ Начало работ : DD.MM.YYYY | I4: Period Covered/Охваченный период | M4: ='Cover of IPC '!D7 -> DD.MM.YYYY - DD.MM.YYYY
A5: DAYWORKS / ПОДЕННАЯ РАБОТА
A6: Item No / Статья № | B6: Description of Work | C6: Unit | D6: Quantity | E6: Unit Cost (USD) | F6: Total Cost (USD) | G6: Cumulative Previous / Совокупный Предыдущий | I6: Current / Текущее | K6: Total / Итого | M6: Remaining / Оставшиеся | O6: Remaining Percentage/ Оставшийся процент
B7: Описание работ | C7: Единица | D7: Количество | E7: Цена за единицу(USD) | F7: Итого (USD) | G7: Quantity Кол-ство | H7: Amount USD | I7: Quantity Кол-ство | J7: Amount USD | K7: Quantity Кол-ство | L7: Amount USD | M7: Quantity Кол-ство | N7: Amount USD | O7: %
D8: Manual Entry | E8: Manual Entry | F8: D*E | G8: Manual Entry | H8: Manual Entry | I8: K-G | J8: I*$E | K8: Manual Entry | L8: K*$E | M8: D-K | N8: M*$E | O8: N/F
F9: =D9*E9 -> 0 | H9: =G9*$E9 -> 0 | I9: =K9-G9 -> 0 | J9: =I9*$E9 -> 0 | L9: =K9*$E9 -> 0 | M9: =D9-$K9 -> 0 | N9: =M9*$E9 -> 0 | O9: =N9/F9 -> #DIV/0!
F11: =D11*E11 -> 0 | H11: =G11*$E11 -> 0 | I11: =K11-G11 -> 0 | J11: =I11*$E11 -> 0 | L11: =K11*$E11 -> 0 | M11: =D11-$K11 -> 0 | N11: =M11*$E11 -> 0 | O11: =N11/F11 -> #DIV/0!
F13: =D13*E13 -> 0 | H13: =G13*$E13 -> 0 | I13: =K13-G13 -> 0 | J13: =I13*$E13 -> 0 | L13: =K13*$E13 -> 0 | M13: =D13-$K13 -> 0 | N13: =M13*$E13 -> 0 | O13: =N13/F13 -> #DIV/0!
F15: =D15*E15 -> 0 | H15: =G15*$E15 -> 0 | I15: =K15-G15 -> 0 | J15: =I15*$E15 -> 0 | L15: =K15*$E15 -> 0 | M15: =D15-$K15 -> 0 | N15: =M15*$E15 -> 0 | O15: =N15/F15 -> #DIV/0!
F17: =D17*E17 -> 0 | H17: =G17*$E17 -> 0 | I17: =K17-G17 -> 0 | J17: =I17*$E17 -> 0 | L17: =K17*$E17 -> 0 | M17: =D17-$K17 -> 0 | N17: =M17*$E17 -> 0 | O17: =N17/F17 -> #DIV/0!
A19: DW.S | B19: TOTAL / ВСЕГО | F19: =SUM(F9:F18) -> 0 | H19: =SUM(H9:H18) -> 0 | J19: =SUM(J9:J18) -> 0 | L19: =SUM(L9:L18) -> 0 | N19: =SUM(N9:N18) -> 0

Sheet Schedule S1
B1: ='Bill Summary'!B1:O1 -> Name of a project / Название котракту
B2: ='Bill Summary'!B2:O2 -> Contract identifier / Идентификатор контракта
B3: ='Bill Summary'!B3:J3 -> IPC # / СПП № #
B4: ='Bill Summary'!B4:C4 -> Start of Works/ Начало работ : DD.MM.YYYY | H4: Period Covered/Охваченный период | M4: ='Cover of IPC '!D7 -> DD.MM.YYYY - DD.MM.YYYY
A5: SCHEDULE S1 / / ТАБЛИЦА S1
A6: Item No / Статья № | B6: Description of Work | C6: Unit | D6: Quantity | E6: Unit Cost (USD) | F6: Total Cost (USD) | G6: Cumulative Previous / Совокупный Предыдущий | I6: Current / Текущее | K6: Total / Итого | M6: Remaining / Оставшиеся | O6: Remaining Percentage/ Оставшийся процент
B7: Описание работ | C7: Единица | D7: Количество | E7: Цена за единицу(USD) | F7: Итого (USD) | G7: Quantity Кол-ство | H7: Amount USD | I7: Quantity Кол-ство | J7: Amount USD | K7: Quantity Кол-ство | L7: Amount USD | M7: Quantity Кол-ство | N7: Amount USD | O7: %
D8: Manual Entry | E8: Manual Entry | F8: D*E | G8: Manual Entry | H8: G*$E | I8: K-G | J8: I*$E | K8: Manual Entry | L8: K*$E | M8: D-$K | N8: M*$E | O8: N/F
F9: =D9*E9 -> 0 | H9: =G9*$E9 -> 0 | I9: =K9-G9 -> 0 | J9: =I9*$E9 -> 0 | L9: =K9*$E9 -> 0 | M9: =D9-$K9 -> 0 | N9: =M9*$E9 -> 0 | O9: =N9/F9 -> #DIV/0!
F11: =D11*E11 -> 0 | H11: =G11*$E11 -> 0 | I11: =K11-G11 -> 0 | J11: =I11*$E11 -> 0 | L11: =K11*$E11 -> 0 | M11: =D11-$K11 -> 0 | N11: =M11*$E11 -> 0 | O11: =N11/F11 -> #DIV/0!
F13: =D13*E13 -> 0 | H13: =G13*$E13 -> 0 | I13: =K13-G13 -> 0 | J13: =I13*$E13 -> 0 | L13: =K13*$E13 -> 0 | M13: =D13-$K13 -> 0 | N13: =M13*$E13 -> 0 | O13: =N13/F13 -> #DIV/0!
F15: =D15*E15 -> 0 | H15: =G15*$E15 -> 0 | I15: =K15-G15 -> 0 | J15: =I15*$E15 -> 0 | L15: =K15*$E15 -> 0 | M15: =D15-$K15 -> 0 | N15: =M15*$E15 -> 0 | O15: =N15/F15 -> #DIV/0!
F17: =D17*E17 -> 0 | H17: =G17*$E17 -> 0 | I17: =K17-G17 -> 0 | J17: =I17*$E17 -> 0 | L17: =K17*$E17 -> 0 | M17: =D17-$K17 -> 0 | N17: =M17*$E17 -> 0 | O17: =N17/F17 -> #DIV/0!
A19: S1.S | B19: TOTAL / ВСЕГО | F19: =SUM(F9:F18) -> 0 | H19: =SUM(H9:H18) -> 0 | J19: =SUM(J9:J18) -> 0 | L19: =SUM(L9:L18) -> 0 | N19: =SUM(N9:N18) -> 0 | O19: =N19/F19 -> #DIV/0!

Sheet Schedule S2
B1: ='Bill Summary'!B1:O1 -> Name of a project / Название котракту
B2: ='Bill Summary'!B2:O2 -> Contract identifier / Идентификатор контракта
B3: ='Bill Summary'!B3:J3 -> IPC # / СПП № #
B4: ='Bill Summary'!B4:C4 -> Start of Works/ Начало работ : DD.MM.YYYY | H4: Period Covered/Охваченный период | M4: ='Cover of IPC '!D7 -> DD.MM.YYYY - DD.MM.YYYY
A5: SCHEDULE S2 / ТАБЛИЦА S2
A6: Item No / Статья № | B6: Description of Work | C6: Unit | D6: Quantity | E6: Unit Cost (USD) | F6: Total Cost (USD) | G6: Cumulative Previous / Совокупный Предыдущий | I6: Current / Текущее | K6: Total / Итого | M6: Remaining / Оставшиеся | O6: Remaining Percentage/ Оставшийся процент
B7: Описание работ | C7: Единица | D7: Количество | E7: Цена за единицу(USD) | F7: Итого (USD) | G7: Quantity Кол-ство | H7: Amount USD | I7: Quantity Кол-ство | J7: Amount USD | K7: Quantity Кол-ство | L7: Amount USD | M7: Quantity Кол-ство | N7: Amount USD | O7: %
D8: Manual Entry | E8: Manual Entry | F8: D*E | G8: Manual Entry | H8: G*$E | I8: K-G | J8: I*$E | K8: Manual Entry | L8: K*$E | M8: D9-$K9 | N8: M*$E | O8: N/F
F9: =D9*E9 -> 0 | H9: =G9*$E9 -> 0 | I9: =K9-G9 -> 0 | J9: =I9*$E9 -> 0 | L9: =K9*$E9 -> 0 | M9: =D9-$K9 -> 0 | N9: =M9*$E9 -> 0 | O9: =N9/F9 -> #DIV/0!
F11: =D11*E11 -> 0 | H11: =G11*$E11 -> 0 | I11: =K11-G11 -> 0 | J11: =I11*$E11 -> 0 | L11: =K11*$E11 -> 0 | M11: =D11-$K11 -> 0 | N11: =M11*$E11 -> 0 | O11: =N11/F11 -> #DIV/0!
F13: =D13*E13 -> 0 | H13: =G13*$E13 -> 0 | I13: =K13-G13 -> 0 | J13: =I13*$E13 -> 0 | L13: =K13*$E13 -> 0 | M13: =D13-$K13 -> 0 | N13: =M13*$E13 -> 0 | O13: =N13/F13 -> #DIV/0!
F15: =D15*E15 -> 0 | H15: =G15*$E15 -> 0 | I15: =K15-G15 -> 0 | J15: =I15*$E15 -> 0 | L15: =K15*$E15 -> 0 | M15: =D15-$K15 -> 0 | N15: =M15*$E15 -> 0 | O15: =N15/F15 -> #DIV/0!
F17: =D17*E17 -> 0 | H17: =G17*$E17 -> 0 | I17: =K17-G17 -> 0 | J17: =I17*$E17 -> 0 | L17: =K17*$E17 -> 0 | M17: =D17-$K17 -> 0 | N17: =M17*$E17 -> 0 | O17: =N17/F17 -> #DIV/0!
F19: =D19*E19 -> 0 | H19: =G19*$E19 -> 0 | I19: =K19-G19 -> 0 | J19: =I19*$E19 -> 0 | L19: =K19*$E19 -> 0 | M19: =D19-$K19 -> 0 | N19: =M19*$E19 -> 0 | O19: =N19/F19 -> #DIV/0!
F21: =D21*E21 -> 0 | H21: =G21*$E21 -> 0 | I21: =K21-G21 -> 0 | J21: =I21*$E21 -> 0 | L21: =K21*$E21 -> 0 | M21: =D21-$K21 -> 0 | N21: =M21*$E21 -> 0 | O21: =N21/F21 -> #DIV/0!
F23: =D23*E23 -> 0 | H23: =G23*$E23 -> 0 | I23: =K23-G23 -> 0 | J23: =I23*$E23 -> 0 | L23: =K23*$E23 -> 0 | M23: =D23-$K23 -> 0 | N23: =M23*$E23 -> 0 | O23: =N23/F23 -> #DIV/0!
F25: =D25*E25 -> 0 | H25: =G25*$E25 -> 0 | I25: =K25-G25 -> 0 | J25: =I25*$E25 -> 0 | L25: =K25*$E25 -> 0 | M25: =D25-$K25 -> 0 | N25: =M25*$E25 -> 0 | O25: =N25/F25 -> #DIV/0!
A27: S2.S | B27: TOTAL / ВСЕГО | F27: =SUM(F9:F26) -> 0 | H27: =SUM(H9:H26) -> 0 | J27: =SUM(J9:J26) -> 0 | L27: =SUM(L9:L26) -> 0 | N27: =SUM(N9:N26) -> 0 | O27: =N27/F27 -> #DIV/0!

Sheet Sch1.  (B)
B1: ='Bill Summary'!B1:O1 -> Name of a project / Название котракту
B2: ='Bill Summary'!B2:O2 -> Contract identifier / Идентификатор контракта
B3: ='Bill Summary'!B3:J3 -> IPC # / СПП № #
B4: ='Bill Summary'!B4:C4 -> Start of Works/ Начало работ : DD.MM.YYYY | T4: Period Covered/Охваченный период | Y4: ='Cover of IPC '!D7 -> DD.MM.YYYY - DD.MM.YYYY
A5: SCHEDULE 1 / ТАБЛИЦА 1
A6: Item No/Статья № | B6: Description of Work | C6: Unit | D6: Quantity | E6: Unit Cost (USD) | F6: Total Cost (USD) | G6: Cumulative Previous/Совокупный Предыдущий | L6: Current / Текущее | Q6: Total / Итого | V6: Remaining / Оставшиеся | AA6: Remaining Percentage/ Оставшийся процент | AB6: Amount payable before leaving the factory (71,43%) Сумма, подлежащая оплате перед отъездом с завода | AD6: After delivery of equipment on site (28,57%) После доставки оборудования на объект
B7: Описание работ | C7: Единица | D7: Количество | E7: Цена за единицу(USD) | F7: Итого (USD) | G7: Amount payable before leaving the factory (71,43%%) Сумма, подлежащая оплате перед отъездом с завода | I7: After delivery of equipment on site (28,57%) После доставки оборудования на объект | K7: Total payment/ Всего платеж | L7: Amount payable before leaving the factory (71,43%%) Сумма, подлежащая оплате перед отъездом с завода | N7: After delivery of equipment on site (28,57%) После доставки оборудования на объект | P7: Total payment/ Всего платеж | Q7: Amount payable before leaving the factory (71,43%%) Сумма, подлежащая оплате перед отъездом с завода | S7: After delivery of equipment on site (28,57%) После доставки оборудования на объект | U7: Total payment/ Всего платеж | V7: Amount payable before leaving the factory (71,43%%) Сумма, подлежащая оплате перед отъездом с завода | X7: After delivery of equipment on site (28,57%) После доставки оборудования на объект | Z7: Total payment/ Всего платеж
G8: Quantity Кол-ство | H8: Amount USD | I8: Quantity Кол-ство | J8: Amount USD | K8: Amount USD | L8: Quantity Кол-ство | M8: Amount USD | N8: Quantity Кол-ство | O8: Amount USD | P8: Amount USD | Q8: Quantity Кол-ство | R8: Amount USD | S8: Quantity Кол-ство | T8: Amount USD | U8: Amount USD | V8: Quantity Кол-ство | W8: Amount USD | X8: Quantity Кол-ство | Y8: Amount USD | Z8: Amount USD | AA8: % | AB8: =50/70 -> 0.71428571 | AD8: =20/70 -> 0.28571429
A9: 1A
A10: 1A1 | D10: Sch1. Supply of Plant CIP (A)'!D:D | E10: Sch1. Supply of Plant CIP (A)'!E:E | F10: D*E | G10: Sch1. Supply of Plant CIP (A)'!G:G | H10: G*$E*$AB$ | I10: Sch1. Supply of Plant CIP (A)'!I:I | J10: I*E*$AD$ | K10: J+H | L10: Q-G | M10: L*$E*$AB$ | N10: S-I | O10: N*$E*$AD$ | P10: O+M | Q10: Sch1. Supply of Plant CIP (A)'!Q:Q | R10: Q*$E*$AB$ | S10: Sch1. Supply of Plant CIP (A)'!S:S | T10: S*$E*$AD$ | U10: T+R | V10: D-$Q | W10: V*$E*$AB$ | X10: D-S | Y10: X*$E*$AD$ | Z10: Y+W | AA10: Z/F
A11: 1.1 | D11: ='Sch1. (A)'!D11:D12 -> 0 | E11: ='Sch1. (A)'!E11:E12 -> 0 | F11: =D11*E11 -> 0 | G11: ='Sch1. (A)'!G11:G12 -> 0 | H11: =G11*$E11*$AB$8 -> 0 | I11: ='Sch1. (A)'!I11:I12 -> 0 | J11: =I11*E11*$AD$8 -> 0 | K11: =J11+H11 -> 0 | L11: =Q11-G11 -> 0 | M11: =L11*$E11*$AB$8 -> 0 | N11: =S11-I11 -> 0 | O11: =N11*$E11*$AD$8 -> 0 | P11: =O11+M11 -> 0 | Q11: ='Sch1. (A)'!Q11:Q12 -> 0 | R11: =Q11*$E11*$AB$8 -> 0 | S11: ='Sch1. (A)'!S11:S12 -> 0 | T11: =S11*$E11*$AD$8 -> 0 | U11: =T11+R11 -> 0 | V11: =D11-$Q11 -> 0 | W11: =V11*$E11*$AB$8 -> 0 | X11: =D11-S11 -> 0 | Y11: =X11*$E11*$AD$8 -> 0 | Z11: =Y11+W11 -> 0 | AA11: =Z11/F11 -> #DIV/0!
A13: 1.2 | D13: ='Sch1. (A)'!D13:D14 -> 0 | E13: ='Sch1. (A)'!E13:E14 -> 0 | F13: =D13*E13 -> 0 | G13: ='Sch1. (A)'!G13:G14 -> 0 | H13: =G13*$E13*$AB$8 -> 0 | I13: ='Sch1. (A)'!I13:I14 -> 0 | J13: =I13*E13*$AD$8 -> 0 | K13: =J13+H13 -> 0 | L13: =Q13-G13 -> 0 | M13: =L13*$E13*$AB$8 -> 0 | N13: =S13-I13 -> 0 | O13: =N13*$E13*$AD$8 -> 0 | P13: =O13+M13 -> 0 | Q13: ='Sch1. (A)'!Q13:Q14 -> 0 | R13: =Q13*$E13*$AB$8 -> 0 | S13: ='Sch1. (A)'!S13:S14 -> 0 | T13: =S13*$E13*$AD$8 -> 0 | U13: =T13+R13 -> 0 | V13: =D13-$Q13 -> 0 | W13: =V13*$E13*$AB$8 -> 0 | X13: =D13-S13 -> 0 | Y13: =X13*$E13*$AD$8 -> 0 | Z13: =Y13+W13 -> 0 | AA13: =Z13/F13 -> #DIV/0!
A15: 1.3 | D15: ='Sch1. (A)'!D15:D16 -> 0 | E15: ='Sch1. (A)'!E15:E16 -> 0 | F15: =D15*E15 -> 0 | G15: ='Sch1. (A)'!G15:G16 -> 0 | H15: =G15*$E15*$AB$8 -> 0 | I15: ='Sch1. (A)'!I15:I16 -> 0 | J15: =I15*E15*$AD$8 -> 0 | K15: =J15+H15 -> 0 | L15: =Q15-G15 -> 0 | M15: =L15*$E15*$AB$8 -> 0 | N15: =S15-I15 -> 0 | O15: =N15*$E15*$AD$8 -> 0 | P15: =O15+M15 -> 0 | Q15: ='Sch1. (A)'!Q15:Q16 -> 0 | R15: =Q15*$E15*$AB$8 -> 0 | S15: ='Sch1. (A)'!S15:S16 -> 0 | T15: =S15*$E15*$AD$8 -> 0 | U15: =T15+R15 -> 0 | V15: =D15-$Q15 -> 0 | W15: =V15*$E15*$AB$8 -> 0 | X15: =D15-S15 -> 0 | Y15: =X15*$E15*$AD$8 -> 0 | Z15: =Y15+W15 -> 0 | AA15: =Z15/F15 -> #DIV/0!
A17: 1.4 | D17: ='Sch1. (A)'!D17:D18 -> 0 | E17: ='Sch1. (A)'!E17:E18 -> 0 | F17: =D17*E17 -> 0 | G17: ='Sch1. (A)'!G17:G18 -> 0 | H17: =G17*$E17*$AB$8 -> 0 | I17: ='Sch1. (A)'!I17:I18 -> 0 | J17: =I17*E17*$AD$8 -> 0 | K17: =J17+H17 -> 0 | L17: =Q17-G17 -> 0 | M17: =L17*$E17*$AB$8 -> 0 | N17: =S17-I17 -> 0 | O17: =N17*$E17*$AD$8 -> 0 | P17: =O17+M17 -> 0 | Q17: ='Sch1. (A)'!Q17:Q18 -> 0 | R17: =Q17*$E17*$AB$8 -> 0 | S17: ='Sch1. (A)'!S17:S18 -> 0 | T17: =S17*$E17*$AD$8 -> 0 | U17: =T17+R17 -> 0 | V17: =D17-$Q17 -> 0 | W17: =V17*$E17*$AB$8 -> 0 | X17: =D17-S17 -> 0 | Y17: =X17*$E17*$AD$8 -> 0 | Z17: =Y17+W17 -> 0 | AA17: =Z17/F17 -> #DIV/0!
A19: 1.S | B19: TOTAL / ВСЕГО | F19: =SUM(#REF!,#REF!,#REF!,#REF!,#REF!,#REF!,#REF!,#REF!,#REF!,#REF!,#REF!,#REF!,#REF!,#REF!,#REF!,#REF!,#REF!,#REF!,#REF!,#REF!,#REF!,#REF!,#REF!,#REF!,#REF!,#REF!,#REF!,#REF!,#REF!,#REF!,#REF!,#REF!,#REF!,#REF!,#REF!,#REF!,#REF!,#REF!,#REF!,#REF!,#REF!,#REF!,#REF!,#REF!,#REF!,#REF!,#REF!,#REF!,#REF!,#REF!,#REF!,#REF!,#REF!,#REF!,#REF!,#REF!,#REF!,#REF!,#REF!,F11:F18) -> #REF! | H19: =SUM(H11:H18) -> 0 | J19: =SUM(J11:J18) -> 0 | K19: =SUM(K11:K18) -> 0 | M19: =SUM(M11:M18) -> 0 | O19: =SUM(O11:O18) -> 0 | P19: =SUM(P11:P18) -> 0 | R19: =SUM(R11:R18) -> 0 | T19: =SUM(T11:T18) -> 0 | U19: =SUM(U11:U18) -> 0 | W19: =SUM(W11:W18) -> 0 | Y19: =SUM(Y11:Y18) -> 0 | Z19: =SUM(Z11:Z18) -> 0 | AA19: =Z19/F19 -> #REF!

Sheet Sch3. (B)
B1: ='Bill Summary'!B1:O1 -> Name of a project / Название котракту
B2: ='Bill Summary'!B2:O2 -> Contract identifier / Идентификатор контракта
B3: ='Bill Summary'!B3:J3 -> IPC # / СПП № #
B4: ='Bill Summary'!B4:C4 -> Start of Works/ Начало работ : DD.MM.YYYY | I4: Period Covered/Охваченный период | M4: ='Cover of IPC '!D7 -> DD.MM.YYYY - DD.MM.YYYY
A5: SCHEDULE 3 / ТАБЛИЦА 3
A6: Item No / Статья № | B6: Description of Work | C6: Unit | D6: Quantity | E6: Unit Cost (USD) | F6: Total Cost (USD) | G6: Cumulative Previous/Совокупный Предыдущий | I6: Current / Текущее | K6: Total / Итого | M6: Remaining / Оставшиеся | O6: Remaining Percentage/ Оставшийся процент
B7: Описание работ | C7: Единица | D7: Количество | E7: Цена за единицу(USD) | F7: Итого (USD) | G7: Quantity Кол-ство | H7: Amount USD | I7: Quantity Кол-ство | J7: Amount USD | K7: Quantity Кол-ство | L7: Amount USD | M7: Quantity Кол-ство | N7: Amount USD | O7: % | P7: 1
D9: Sch3. Design Services (A)'!D:D | E9: Sch3. Design Services (A)'!E:E | F9: D*E | G9: Sch3. Design Services (A)'!G:G | H9: G*$E*$P$ | I9: K-G | J9: I*$E*$P$ | K9: Sch3. Design Services (A)'!K:K | L9: K*$E*$P$ | M9: D-K | N9: M*$E*$P$ | O9: N/(F*$P$7)
D10: ='Sch3. (A)'!D10:D11 -> 0 | E10: ='Sch3. (A)'!E10:E11 -> 0 | F10: =D10*E10 -> 0 | G10: ='Sch3. (A)'!G10:G11 -> 0 | H10: =G10*$E10*$P$7 -> 0 | I10: =K10-G10 -> 0 | J10: =I10*$E10*$P$7 -> 0 | K10: ='Sch3. (A)'!K10:K11 -> 0 | L10: =K10*$E10*$P$7 -> 0 | M10: =D10-$K10 -> 0 | N10: =M10*$E10*$P$7 -> 0 | O10: =N10/(F10*$P$7) -> #DIV/0!
D12: ='Sch3. (A)'!D12:D13 -> 0 | E12: ='Sch3. (A)'!E12:E13 -> 0 | F12: =D12*E12 -> 0 | G12: ='Sch3. (A)'!G12:G13 -> 0 | H12: =G12*$E12*$P$7 -> 0 | I12: =K12-G12 -> 0 | J12: =I12*$E12*$P$7 -> 0 | K12: ='Sch3. (A)'!K12:K13 -> 0 | L12: =K12*$E12*$P$7 -> 0 | M12: =D12-$K12 -> 0 | N12: =M12*$E12*$P$7 -> 0 | O12: =N12/(F12*$P$7) -> #DIV/0!
D14: ='Sch3. (A)'!D14:D15 -> 0 | E14: ='Sch3. (A)'!E14:E15 -> 0 | F14: =D14*E14 -> 0 | G14: ='Sch3. (A)'!G14:G15 -> 0 | H14: =G14*$E14*$P$7 -> 0 | I14: =K14-G14 -> 0 | J14: =I14*$E14*$P$7 -> 0 | K14: ='Sch3. (A)'!K14:K15 -> 0 | L14: =K14*$E14*$P$7 -> 0 | M14: =D14-$K14 -> 0 | N14: =M14*$E14*$P$7 -> 0 | O14: =N14/(F14*$P$7) -> #DIV/0!
D16: ='Sch3. (A)'!D16:D17 -> 0 | E16: ='Sch3. (A)'!E16:E17 -> 0 | F16: =D16*E16 -> 0 | G16: ='Sch3. (A)'!G16:G17 -> 0 | H16: =G16*$E16*$P$7 -> 0 | I16: =K16-G16 -> 0 | J16: =I16*$E16*$P$7 -> 0 | K16: ='Sch3. (A)'!K16:K17 -> 0 | L16: =K16*$E16*$P$7 -> 0 | M16: =D16-$K16 -> 0 | N16: =M16*$E16*$P$7 -> 0 | O16: =N16/(F16*$P$7) -> #DIV/0!
D18: ='Sch3. (A)'!D18:D19 -> 0 | E18: ='Sch3. (A)'!E18:E19 -> 0 | F18: =D18*E18 -> 0 | G18: ='Sch3. (A)'!G18:G19 -> 0 | H18: =G18*$E18*$P$7 -> 0 | I18: =K18-G18 -> 0 | J18: =I18*$E18*$P$7 -> 0 | K18: ='Sch3. (A)'!K18:K19 -> 0 | L18: =K18*$E18*$P$7 -> 0 | M18: =D18-$K18 -> 0 | N18: =M18*$E18*$P$7 -> 0 | O18: =N18/(F18*$P$7) -> #DIV/0!
A20: 3.S | B20: TOTAL / ВСЕГО | F20: =SUM(F10:F19) -> 0 | H20: =SUM(H10:H19) -> 0 | J20: =SUM(J10:J19) -> 0 | L20: =SUM(L10:L19) -> 0 | N20: =SUM(N10:N19) -> 0 | O20: =N20/F20 -> #DIV/0!

Sheet Sch4. (B)
B1: ='Bill Summary'!B1:O1 -> Name of a project / Название котракту
B2: ='Bill Summary'!B2:O2 -> Contract identifier / Идентификатор контракта
B3: ='Bill Summary'!B3:J3 -> IPC # / СПП № #
B4: ='Bill Summary'!B4:C4 -> Start of Works/ Начало работ : DD.MM.YYYY | I4: Period Covered/Охваченный период | M4: ='Cover of IPC '!D7 -> DD.MM.YYYY - DD.MM.YYYY
A5: SCHEDULE 4. / ТАБЛИЦА 4.
A6: Item No / Статья № | B6: Description of Work | C6: Unit | D6: Quantity | E6: Unit Cost (USD) | F6: Total Cost (USD) | G6: Cumulative Previous/Совокупный Предыдущий | I6: Current / Текущее | K6: Total / Итого | M6: Remaining / Оставшиеся | O6: Remaining Percentage/ Оставшийся процент
B7: Описание работ | C7: Единица | D7: Количество | E7: Цена за единицу(USD) | F7: Итого (USD) | G7: Quantity Кол-ство | H7: Amount USD | I7: Quantity Кол-ство | J7: Amount USD | K7: Quantity Кол-ство | L7: Amount USD | M7: Quantity Кол-ство | N7: Amount USD | O7: % | P7: 1
D9: Sch4. Installation (A)'!D:D | E9: Sch4. Installation (A)'!E:E | F9: D*E | G9: Sch4. Installation (A)'!G:G | H9: G*$E*$P$7 | I9: K-G | J9: I*$E*$P$7 | K9: Sch4. Installation (A)'!K:K | L9: K*$E*$P$7 | M9: D-K | N9: M*$E*$P$7 | O9: N/(F*$P$7)
D10: ='Sch4. (A)'!D10:D11 -> 0 | E10: ='Sch4. (A)'!E10:E11 -> 0 | F10: =D10*E10 -> 0 | G10: ='Sch4. (A)'!G10:G11 -> 0 | H10: =G10*$E10*$P$7 -> 0 | I10: =K10-G10 -> 0 | J10: =I10*$E10*$P$7 -> 0 | K10: ='Sch4. (A)'!K10:K11 -> 0 | L10: =K10*$E10*$P$7 -> 0 | M10: =D10-$K10 -> 0 | N10: =M10*$E10*$P$7 -> 0 | O10: =N10/(F10*$P$7) -> #DIV/0!
D12: ='Sch4. (A)'!D12:D13 -> 0 | E12: ='Sch4. (A)'!E12:E13 -> 0 | F12: =D12*E12 -> 0 | G12: ='Sch4. (A)'!G12:G13 -> 0 | H12: =G12*$E12*$P$7 -> 0 | I12: =K12-G12 -> 0 | J12: =I12*$E12*$P$7 -> 0 | K12: ='Sch4. (A)'!K12:K13 -> 0 | L12: =K12*$E12*$P$7 -> 0 | M12: =D12-$K12 -> 0 | N12: =M12*$E12*$P$7 -> 0 | O12: =N12/(F12*$P$7) -> #DIV/0!
D15: ='Sch4. (A)'!D15:D16 -> 0 | E15: ='Sch4. (A)'!E15:E16 -> 0 | F15: =D15*E15 -> 0 | G15: ='Sch4. (A)'!G15:G16 -> 0 | H15: =G15*$E15*$P$7 -> 0 | I15: =K15-G15 -> 0 | J15: =I15*$E15*$P$7 -> 0 | K15: ='Sch4. (A)'!K15:K16 -> 0 | L15: =K15*$E15*$P$7 -> 0 | M15: =D15-$K15 -> 0 | N15: =M15*$E15*$P$7 -> 0 | O15: =N15/(F15*$P$7) -> #DIV/0!
D17: ='Sch4. (A)'!D17:D18 -> 0 | E17: ='Sch4. (A)'!E17:E18 -> 0 | F17: =D17*E17 -> 0 | G17: ='Sch4. (A)'!G17:G18 -> 0 | H17: =G17*$E17*$P$7 -> 0 | I17: =K17-G17 -> 0 | J17: =I17*$E17*$P$7 -> 0 | K17: ='Sch4. (A)'!K17:K18 -> 0 | L17: =K17*$E17*$P$7 -> 0 | M17: =D17-$K17 -> 0 | N17: =M17*$E17*$P$7 -> 0 | O17: =N17/(F17*$P$7) -> #DIV/0!
D19: ='Sch4. (A)'!D19:D20 -> 0 | E19: ='Sch4. (A)'!E19:E20 -> 0 | F19: =D19*E19 -> 0 | G19: ='Sch4. (A)'!G19:G20 -> 0 | H19: =G19*$E19*$P$7 -> 0 | I19: =K19-G19 -> 0 | J19: =I19*$E19*$P$7 -> 0 | K19: ='Sch4. (A)'!K19:K20 -> 0 | L19: =K19*$E19*$P$7 -> 0 | M19: =D19-$K19 -> 0 | N19: =M19*$E19*$P$7 -> 0 | O19: =N19/(F19*$P$7) -> #DIV/0!
D21: ='Sch4. (A)'!D21:D22 -> 0 | E21: ='Sch4. (A)'!E21:E22 -> 0 | F21: =D21*E21 -> 0 | G21: ='Sch4. (A)'!G21:G22 -> 0 | H21: =G21*$E21*$P$7 -> 0 | I21: =K21-G21 -> 0 | J21: =I21*$E21*$P$7 -> 0 | K21: ='Sch4. (A)'!K21:K22 -> 0 | L21: =K21*$E21*$P$7 -> 0 | M21: =D21-$K21 -> 0 | N21: =M21*$E21*$P$7 -> 0 | O21: =N21/(F21*$P$7) -> #DIV/0!
D23: ='Sch4. (A)'!D23:D24 -> 0 | E23: ='Sch4. (A)'!E23:E24 -> 0 | F23: =D23*E23 -> 0 | G23: ='Sch4. (A)'!G23:G24 -> 0 | H23: =G23*$E23*$P$7 -> 0 | I23: =K23-G23 -> 0 | J23: =I23*$E23*$P$7 -> 0 | K23: ='Sch4. (A)'!K23:K24 -> 0 | L23: =K23*$E23*$P$7 -> 0 | M23: =D23-$K23 -> 0 | N23: =M23*$E23*$P$7 -> 0 | O23: =N23/(F23*$P$7) -> #DIV/0!
D25: ='Sch4. (A)'!D25:D26 -> 0 | E25: ='Sch4. (A)'!E25:E26 -> 0 | F25: =D25*E25 -> 0 | G25: ='Sch4. (A)'!G25:G26 -> 0 | H25: =G25*$E25*$P$7 -> 0 | I25: =K25-G25 -> 0 | J25: =I25*$E25*$P$7 -> 0 | K25: ='Sch4. (A)'!K25:K26 -> 0 | L25: =K25*$E25*$P$7 -> 0 | M25: =D25-$K25 -> 0 | N25: =M25*$E25*$P$7 -> 0 | O25: =N25/(F25*$P$7) -> #DIV/0!
D27: ='Sch4. (A)'!D27:D28 -> 0 | E27: ='Sch4. (A)'!E27:E28 -> 0 | F27: =D27*E27 -> 0 | G27: ='Sch4. (A)'!G27:G28 -> 0 | H27: =G27*$E27*$P$7 -> 0 | I27: =K27-G27 -> 0 | J27: =I27*$E27*$P$7 -> 0 | K27: ='Sch4. (A)'!K27:K28 -> 0 | L27: =K27*$E27*$P$7 -> 0 | M27: =D27-$K27 -> 0 | N27: =M27*$E27*$P$7 -> 0 | O27: =N27/(F27*$P$7) -> #DIV/0!
D29: ='Sch4. (A)'!D29:D30 -> 0 | E29: ='Sch4. (A)'!E29:E30 -> 0 | F29: =D29*E29 -> 0 | G29: ='Sch4. (A)'!G29:G30 -> 0 | H29: =G29*$E29*$P$7 -> 0 | I29: =K29-G29 -> 0 | J29: =I29*$E29*$P$7 -> 0 | K29: ='Sch4. (A)'!K29:K30 -> 0 | L29: =K29*$E29*$P$7 -> 0 | M29: =D29-$K29 -> 0 | N29: =M29*$E29*$P$7 -> 0 | O29: =N29/(F29*$P$7) -> #DIV/0!
D31: ='Sch4. (A)'!D31:D32 -> 0 | E31: ='Sch4. (A)'!E31:E32 -> 0 | F31: =D31*E31 -> 0 | G31: ='Sch4. (A)'!G31:G32 -> 0 | H31: =G31*$E31*$P$7 -> 0 | I31: =K31-G31 -> 0 | J31: =I31*$E31*$P$7 -> 0 | K31: ='Sch4. (A)'!K31:K32 -> 0 | L31: =K31*$E31*$P$7 -> 0 | M31: =D31-$K31 -> 0 | N31: =M31*$E31*$P$7 -> 0 | O31: =N31/(F31*$P$7) -> #DIV/0!
A33: 4.S | B33: TOTAL / ВСЕГО | F33: =SUM(F10:F32) -> 0 | H33: =SUM(H10:H32) -> 0 | J33: =SUM(J10:J32) -> 0 | L33: =SUM(L10:L32) -> 0 | N33: =SUM(N10:N32) -> 0 | O33: =N33/F33 -> #DIV/0!

Sheet Sheet1
